<?xml version="1.0" ?>
<!-- =================================================================================== -->
<!-- |    This document was autogenerated by xacro from experiment.xacro               | -->
<!-- |    EDITING THIS FILE BY HAND IS NOT RECOMMENDED                                 | -->
<!-- =================================================================================== -->
<robot name="body" xmlns:xacro="http://www.ros.org/wiki/xacro">
  <!-- ROS Control -->
  <!-- For Effort controllers -->
  <!-- For Position controllers -->
  <gazebo>
    <plugin filename="libgazebo_ros_control.so" name="ros_control">
      </plugin>
  </gazebo>
  <link name="world"/>
  <joint name="fixed" type="fixed">
    <parent link="world"/>
    <child link="column"/>
  </joint>
  <link name="neck">
    <inertial>
      <origin xyz="-0.003053 -0.038651 -0.019268"/>
      <mass value="0.97559947"/>
      <inertia ixx="3.1081800" ixy="-0.25460189" ixz="2.0318174" iyy="6.3787776" iyz="0.16417863" izz="5.3316425"/>
    </inertial>
    <visual>
      <origin rpy="0 0 0" xyz="0 0 0"/>
      <!--origin xyz="-0.0235 0 -0.03525" rpy="0 0 0" /-->
      <geometry>
        <box size="0.0357142857143 0.0142857142857 0.0151428571429"/>
      </geometry>
    </visual>
  </link>
  <link name="head">
    <inertial>
      <origin xyz="-0.003053 -0.038651 -0.019268"/>
      <mass value="0.97559947"/>
      <inertia ixx="3.1081800" ixy="-0.25460189" ixz="2.0318174" iyy="6.3787776" iyz="0.16417863" izz="5.3316425"/>
    </inertial>
    <visual>
      <origin rpy="0 0 0" xyz="0.0625 0 0"/>
      <!--origin xyz="-0.0235 0 -0.03525" rpy="0 0 0" /-->
      <geometry>
        <box size="0.125 0.08 0.0636"/>
      </geometry>
    </visual>
  </link>
  <link name="tail">
    <inertial>
      <origin xyz="-0.003053 -0.038651 -0.019268"/>
      <mass value="0.97559947"/>
      <inertia ixx="3.1081800" ixy="-0.25460189" ixz="2.0318174" iyy="6.3787776" iyz="0.16417863" izz="5.3316425"/>
    </inertial>
    <visual>
      <origin rpy="0 -1.57079632679 0" xyz="-0.250 0 0"/>
      <!--origin xyz="-0.0235 0 -0.03525" rpy="0 0 0" /-->
      <geometry>
        <mesh filename="package://simple_biped/cone.stl" scale="0.005 0.005 0.005"/>
      </geometry>
    </visual>
  </link>
  <link name="base_link"/>
  <joint name="body_to_tail" type="fixed">
    <parent link="body"/>
    <child link="tail"/>
    <origin rpy="0 0 0" xyz="-0.125 0 0"/>
  </joint>
  <joint name="body_to_neck" type="fixed">
    <parent link="body"/>
    <child link="neck"/>
    <origin rpy="0 0 0" xyz="0.125 0 0.0353333333333"/>
  </joint>
  <joint name="neck_to_head" type="fixed">
    <parent link="neck"/>
    <child link="head"/>
    <origin rpy="0 0 0" xyz="0.0178571428571 0 0"/>
  </joint>
  <joint name="base_link_to_body" type="fixed">
    <parent link="base_link"/>
    <child link="body"/>
  </joint>
  <joint name="column_to_beam" type="continuous">
    <parent link="column"/>
    <child link="beam"/>
    <axis xyz="0 0 1"/>
    <origin rpy="0 0 0" xyz="0 0.503 0.53"/>
  </joint>
  <joint name="beam_to_support" type="fixed">
    <parent link="beam"/>
    <child link="support"/>
    <origin rpy="0 0 0" xyz="0 0.503 -0.595"/>
  </joint>
  <joint name="support_to_base_link" type="fixed">
    <parent link="support"/>
    <child link="base_link"/>
    <origin rpy="0 0 0" xyz="0 0 -0.595"/>
  </joint>
  <link name="column">
    <inertial>
      <origin xyz="-0.003053 -0.038651 -0.019268"/>
      <mass value="0.97559947"/>
      <inertia ixx="3.1081800" ixy="-0.25460189" ixz="2.0318174" iyy="6.3787776" iyz="0.16417863" izz="5.3316425"/>
    </inertial>
    <visual>
      <!--origin xyz="-0.0235 0 -0.03525" rpy="0 0 0" /-->
      <origin rpy="0 0 0" xyz="0 0 0"/>
      <geometry>
        <box size="0.05 0.05 1.06"/>
      </geometry>
    </visual>
    <collision>
      <geometry>
        <box size="0.05 0.05 1.06"/>
      </geometry>
    </collision>
  </link>
  <link name="support">
    <inertial>
      <origin xyz="-0.003053 -0.038651 -0.019268"/>
      <mass value="0.97559947"/>
      <inertia ixx="3.1081800" ixy="-0.25460189" ixz="2.0318174" iyy="6.3787776" iyz="0.16417863" izz="5.3316425"/>
    </inertial>
    <visual>
      <origin rpy="0 0 0" xyz="0 0 0"/>
      <geometry>
        <box size="0.05 0.05 1.19"/>
      </geometry>
    </visual>
    <collision>
      <geometry>
        <box size="0.05 0.05 1.19"/>
      </geometry>
    </collision>
  </link>
  <link name="beam">
    <inertial>
      <origin xyz="-0.003053 -0.038651 -0.019268"/>
      <mass value="0.97559947"/>
      <inertia ixx="3.1081800" ixy="-0.25460189" ixz="2.0318174" iyy="6.3787776" iyz="0.16417863" izz="5.3316425"/>
    </inertial>
    <visual>
      <!--origin xyz="-0.0235 0 -0.03525" rpy="0 0 0" /-->
      <origin rpy="0 0 0" xyz="0 0 0"/>
      <geometry>
        <box size="0.05 1.006 0.05 "/>
      </geometry>
    </visual>
    <collision>
      <geometry>
        <box size="0.05 1.006 0.05 "/>
      </geometry>
    </collision>
  </link>
  <link name="body">
    <inertial>
      <origin xyz="-0.003053 -0.038651 -0.019268"/>
      <mass value="0.97559947"/>
      <inertia ixx="3.1081800" ixy="-0.25460189" ixz="2.0318174" iyy="6.3787776" iyz="0.16417863" izz="5.3316425"/>
    </inertial>
    <visual>
      <!--origin xyz="-0.0235 0 -0.03525" rpy="0 0 0" /-->
      <origin rpy="0 0 0" xyz="0 0 0"/>
      <geometry>
        <box size="0.25 0.1 0.106"/>
      </geometry>
    </visual>
    <collision>
      <geometry>
        <box size="0.25 0.1 0.106"/>
      </geometry>
    </collision>
  </link>
  <!-- Arm -->
  <!--xacro:property name="body_height" value="0.106" /-->
  <!--xacro:property name="body_width" value="0.109" /-->
  <!--xacro:property name="body_large" value="0.102" /-->
  <!-- Left Arm -->
  <!-- Transmissions -->
  <transmission name="l_pelvis_joint_transmission">
    <type>transmission_interface/SimpleTransmission</type>
    <joint name="l_pelvis_joint">
      <hardwareInterface>EffortJointInterface</hardwareInterface>
    </joint>
    <actuator name="l_pelvis_joint_motor">
      <hardwareInterface>EffortJointInterface</hardwareInterface>
      <mechanicalReduction>1</mechanicalReduction>
    </actuator>
  </transmission>
  <transmission name="l_thigh_yaw_joint_transmission">
    <type>transmission_interface/SimpleTransmission</type>
    <joint name="l_thigh_yaw_joint">
      <hardwareInterface>EffortJointInterface</hardwareInterface>
    </joint>
    <actuator name="l_thigh_yaw_joint_motor">
      <hardwareInterface>EffortJointInterface</hardwareInterface>
      <mechanicalReduction>1</mechanicalReduction>
    </actuator>
  </transmission>
  <transmission name="l_thigh_pitch_joint_transmission">
    <type>transmission_interface/SimpleTransmission</type>
    <joint name="l_thigh_pitch_joint">
      <hardwareInterface>EffortJointInterface</hardwareInterface>
    </joint>
    <actuator name="l_thigh_pitch_joint_motor">
      <hardwareInterface>EffortJointInterface</hardwareInterface>
      <mechanicalReduction>1</mechanicalReduction>
    </actuator>
  </transmission>
  <transmission name="l_tibia_joint_transmission">
    <type>transmission_interface/SimpleTransmission</type>
    <joint name="l_tibia_joint">
      <hardwareInterface>EffortJointInterface</hardwareInterface>
    </joint>
    <actuator name="l_tibia_joint_motor">
      <hardwareInterface>EffortJointInterface</hardwareInterface>
      <mechanicalReduction>1</mechanicalReduction>
    </actuator>
  </transmission>
  <transmission name="l_ankle_joint_transmission">
    <type>transmission_interface/SimpleTransmission</type>
    <joint name="l_ankle_joint">
      <hardwareInterface>EffortJointInterface</hardwareInterface>
    </joint>
    <actuator name="l_ankle_joint_motor">
      <hardwareInterface>EffortJointInterface</hardwareInterface>
      <mechanicalReduction>1</mechanicalReduction>
    </actuator>
  </transmission>
  <transmission name="l_phalange_joint_transmission">
    <type>transmission_interface/SimpleTransmission</type>
    <joint name="l_phalange_joint">
      <hardwareInterface>EffortJointInterface</hardwareInterface>
    </joint>
    <actuator name="l_phalange_joint_motor">
      <hardwareInterface>EffortJointInterface</hardwareInterface>
      <mechanicalReduction>1</mechanicalReduction>
    </actuator>
  </transmission>
  <link name="l_pelvis">
    <inertial>
      <origin xyz="0.000000 0.000480 0.018437"/>
      <mass value="0.167"/>
      <inertia ixx="0.12259691" ixy="0.00071127469" ixz="0.00081143913" iyx="0.00071127469" iyy="0.11066637" iyz="-0.0071635476" izx="0.00081143913" izy="-0.0071635476" izz="0.041877668"/>
    </inertial>
    <visual>
      <origin rpy="0 0 0" xyz="0 0 -0.014326"/>
      <geometry>
        <box size="0.045 0.08175 0.028652"/>
      </geometry>
    </visual>
    <collision>
      <origin rpy="0 0 0" xyz="0 0 -0.014326"/>
      <geometry>
        <box size="0.045 0.08175 0.028652"/>
      </geometry>
    </collision>
  </link>
  <link name="l_thigh_yaw">
    <inertial>
      <origin xyz="0.000079 0.018242 0.013873"/>
      <mass value="0.11904336"/>
      <inertia ixx="0.097950272" ixy="0.0012119368" ixz="-0.00021223016" iyx="0.00122119368" iyy="0.032848287" iyz="-0.0019474021" izx="-0.00021223016" izy="-0.0019474021" izz="0.11493509"/>
    </inertial>
    <visual>
      <origin rpy="0 0 0" xyz="0 0 0"/>
      <geometry>
        <box size="0.001 0.001 0.001"/>
      </geometry>
    </visual>
    <collision>
      <geometry>
        <box size="0.001 0.001 0.001"/>
      </geometry>
    </collision>
  </link>
  <link name="l_thigh">
    <inertial>
      <origin xyz="-0.062965 -0.000323 0.000692"/>
      <mass value="0.11904336"/>
      <inertia ixx="0.097950272" ixy="0.0012119368" ixz="-0.00021223016" iyx="0.00122119368" iyy="0.032848287" iyz="-0.0019474021" izx="-0.00021223016" izy="-0.0019474021" izz="0.11493509"/>
    </inertial>
    <visual>
      <origin rpy="0 0 0" xyz="0 0 -0.0625"/>
      <geometry>
        <box size="0.045 0.035 0.125"/>
      </geometry>
    </visual>
    <collision>
      <origin rpy="0 0 0" xyz="0 0 -0.0625"/>
      <geometry>
        <box size="0.045 0.035 0.125"/>
      </geometry>
    </collision>
  </link>
  <link name="l_tibia">
    <inertial>
      <origin xyz="-0.053955 0.006548 -0.000592"/>
      <mass value="0.070309794"/>
      <inertia ixx="0.093369608" ixy="-0.00093567395" ixz="-0.00023992085" iyx="-0.00093567395" iyy="0.046295534" iyz="-0.012858493" izx="-0.00023992085" izy="-0.012858493" izz="0.11351516"/>
    </inertial>
    <visual>
      <origin rpy="0 0 0" xyz="0 0 -0.065"/>
      <geometry>
        <box size="0.045 0.035 0.13"/>
      </geometry>
    </visual>
    <collision>
      <origin rpy="0 0 0" xyz="0 0 -0.065"/>
      <geometry>
        <box size="0.045 0.035 0.13"/>
      </geometry>
    </collision>
  </link>
  <link name="l_ankle">
    <inertial>
      <origin xyz="-0.000214 -0.018536 0.013873"/>
      <mass value="0.16710792"/>
      <inertia ixx="0.12079175" ixy="-0.00079781067" ixz="-0.00039322246" iyx="-0.00079781067" iyy="0.10885465" iyz="0.0070770117" izx="-0.00039322246" izy="0.0070770117" izz="0.041871103"/>
    </inertial>
    <visual>
      <origin rpy="0 0 0" xyz="0 0 -0.03725"/>
      <geometry>
        <box size="0.045 0.035 0.0745"/>
      </geometry>
    </visual>
    <collision>
      <origin rpy="0 0 0" xyz="0 0 -0.03725"/>
      <geometry>
        <box size="0.045 0.035 0.0745"/>
      </geometry>
    </collision>
  </link>
  <link name="l_phalange">
    <inertial>
      <origin xyz="-0.000214 -0.018536 0.013873"/>
      <mass value="0.16710792"/>
      <inertia ixx="0.12079175" ixy="-0.00079781067" ixz="-0.00039322246" iyx="-0.00079781067" iyy="0.10885465" iyz="0.0070770117" izx="-0.00039322246" izy="0.0070770117" izz="0.041871103"/>
    </inertial>
    <visual>
      <origin rpy="0 0 0" xyz="0 0 -0.03725"/>
      <geometry>
        <box size="0.02 0.02 0.0745"/>
      </geometry>
    </visual>
    <collision>
      <origin rpy="0 0 0" xyz="0 0 -0.03725"/>
      <geometry>
        <box size="0.02 0.02 0.0745"/>
      </geometry>
    </collision>
  </link>
  <joint name="l_pelvis_joint" type="revolute">
    <parent link="body"/>
    <child link="l_pelvis"/>
    <origin rpy="0 0 0" xyz="-0.0416666666667 -0.05 0.0212"/>
    <axis xyz="0 0 1"/>
    <limit effort="10" lower="0" upper="0" velocity="5.6548668"/>
  </joint>
  <joint name="l_thigh_yaw_joint" type="revolute">
    <parent link="l_pelvis"/>
    <child link="l_thigh_yaw"/>
    <origin rpy="0 0 0" xyz="0 -0.040875 -0.028652"/>
    <axis xyz="0 0 1"/>
    <limit effort="10" lower="0" upper="0" velocity="5.6548668"/>
  </joint>
  <joint name="l_thigh_pitch_joint" type="revolute">
    <parent link="l_thigh_yaw"/>
    <child link="l_thigh"/>
    <origin rpy="0 0 0" xyz="0 0 0"/>
    <axis xyz="0 1 0"/>
    <limit effort="10" lower="-1.308996939" upper="0.785398163397" velocity="5.6548668"/>
  </joint>
  <joint name="l_tibia_joint" type="revolute">
    <parent link="l_thigh"/>
    <child link="l_tibia"/>
    <origin rpy="0 0 0" xyz="0 0 -0.125"/>
    <axis xyz="0 1 0"/>
    <limit effort="10" lower="0.0" upper="2.61799387799" velocity="5.6548668"/>
  </joint>
  <joint name="l_ankle_joint" type="revolute">
    <parent link="l_tibia"/>
    <child link="l_ankle"/>
    <origin rpy="0 0 0" xyz="0 0 -0.13"/>
    <axis xyz="0 1 0"/>
    <limit effort="10" lower="-1.57079632679" upper="0.0" velocity="5.6548668"/>
  </joint>
  <joint name="l_phalange_joint" type="revolute">
    <parent link="l_ankle"/>
    <child link="l_phalange"/>
    <origin rpy="0 0 0" xyz="0 0 -0.0745"/>
    <axis xyz="0 1 0"/>
    <limit effort="10" lower="-0.785398163397" upper="0" velocity="5.6548668"/>
  </joint>
  <!-- Right Arm -->
  <!-- Transmissions -->
  <transmission name="r_pelvis_joint_transmission">
    <type>transmission_interface/SimpleTransmission</type>
    <joint name="r_pelvis_joint">
      <hardwareInterface>EffortJointInterface</hardwareInterface>
    </joint>
    <actuator name="r_pelvis_joint_motor">
      <hardwareInterface>EffortJointInterface</hardwareInterface>
      <mechanicalReduction>1</mechanicalReduction>
    </actuator>
  </transmission>
  <transmission name="r_thigh_yaw_joint_transmission">
    <type>transmission_interface/SimpleTransmission</type>
    <joint name="r_thigh_yaw_joint">
      <hardwareInterface>EffortJointInterface</hardwareInterface>
    </joint>
    <actuator name="r_thigh_yaw_joint_motor">
      <hardwareInterface>EffortJointInterface</hardwareInterface>
      <mechanicalReduction>1</mechanicalReduction>
    </actuator>
  </transmission>
  <transmission name="r_thigh_pitch_joint_transmission">
    <type>transmission_interface/SimpleTransmission</type>
    <joint name="r_thigh_pitch_joint">
      <hardwareInterface>EffortJointInterface</hardwareInterface>
    </joint>
    <actuator name="r_thigh_pitch_joint_motor">
      <hardwareInterface>EffortJointInterface</hardwareInterface>
      <mechanicalReduction>1</mechanicalReduction>
    </actuator>
  </transmission>
  <transmission name="r_tibia_joint_transmission">
    <type>transmission_interface/SimpleTransmission</type>
    <joint name="r_tibia_joint">
      <hardwareInterface>EffortJointInterface</hardwareInterface>
    </joint>
    <actuator name="r_tibia_joint_motor">
      <hardwareInterface>EffortJointInterface</hardwareInterface>
      <mechanicalReduction>1</mechanicalReduction>
    </actuator>
  </transmission>
  <transmission name="r_ankle_joint_transmission">
    <type>transmission_interface/SimpleTransmission</type>
    <joint name="r_ankle_joint">
      <hardwareInterface>EffortJointInterface</hardwareInterface>
    </joint>
    <actuator name="r_ankle_joint_motor">
      <hardwareInterface>EffortJointInterface</hardwareInterface>
      <mechanicalReduction>1</mechanicalReduction>
    </actuator>
  </transmission>
  <transmission name="r_phalange_joint_transmission">
    <type>transmission_interface/SimpleTransmission</type>
    <joint name="r_phalange_joint">
      <hardwareInterface>EffortJointInterface</hardwareInterface>
    </joint>
    <actuator name="r_phalange_joint_motor">
      <hardwareInterface>EffortJointInterface</hardwareInterface>
      <mechanicalReduction>1</mechanicalReduction>
    </actuator>
  </transmission>
  <link name="r_pelvis">
    <inertial>
      <origin xyz="0.000000 0.000480 0.018437"/>
      <mass value="0.167"/>
      <inertia ixx="0.12259691" ixy="0.00071127469" ixz="0.00081143913" iyx="0.00071127469" iyy="0.11066637" iyz="-0.0071635476" izx="0.00081143913" izy="-0.0071635476" izz="0.041877668"/>
    </inertial>
    <visual>
      <origin rpy="0 0 0" xyz="0 0 -0.014326"/>
      <geometry>
        <box size="0.045 0.08175 0.028652"/>
      </geometry>
    </visual>
    <collision>
      <origin rpy="0 0 0" xyz="0 0 -0.014326"/>
      <geometry>
        <box size="0.045 0.08175 0.028652"/>
      </geometry>
    </collision>
  </link>
  <link name="r_thigh_yaw">
    <inertial>
      <origin xyz="0.000079 0.018242 0.013873"/>
      <mass value="0.11904336"/>
      <inertia ixx="0.097950272" ixy="0.0012119368" ixz="-0.00021223016" iyx="0.00122119368" iyy="0.032848287" iyz="-0.0019474021" izx="-0.00021223016" izy="-0.0019474021" izz="0.11493509"/>
    </inertial>
    <visual>
      <origin rpy="0 0 0" xyz="0 0 0"/>
      <geometry>
        <box size="0.001 0.001 0.001"/>
      </geometry>
    </visual>
    <collision>
      <geometry>
        <box size="0.001 0.001 0.001"/>
      </geometry>
    </collision>
  </link>
  <link name="r_thigh">
    <inertial>
      <origin xyz="-0.062965 -0.000323 0.000692"/>
      <mass value="0.11904336"/>
      <inertia ixx="0.097950272" ixy="0.0012119368" ixz="-0.00021223016" iyx="0.00122119368" iyy="0.032848287" iyz="-0.0019474021" izx="-0.00021223016" izy="-0.0019474021" izz="0.11493509"/>
    </inertial>
    <visual>
      <origin rpy="0 0 0" xyz="0 0 -0.0625"/>
      <geometry>
        <box size="0.045 0.035 0.125"/>
      </geometry>
    </visual>
    <collision>
      <origin rpy="0 0 0" xyz="0 0 -0.0625"/>
      <geometry>
        <box size="0.045 0.035 0.125"/>
      </geometry>
    </collision>
  </link>
  <link name="r_tibia">
    <inertial>
      <origin xyz="-0.053955 0.006548 -0.000592"/>
      <mass value="0.070309794"/>
      <inertia ixx="0.093369608" ixy="-0.00093567395" ixz="-0.00023992085" iyx="-0.00093567395" iyy="0.046295534" iyz="-0.012858493" izx="-0.00023992085" izy="-0.012858493" izz="0.11351516"/>
    </inertial>
    <visual>
      <origin rpy="0 0 0" xyz="0 0 -0.065"/>
      <geometry>
        <box size="0.045 0.035 0.13"/>
      </geometry>
    </visual>
    <collision>
      <origin rpy="0 0 0" xyz="0 0 -0.065"/>
      <geometry>
        <box size="0.045 0.035 0.13"/>
      </geometry>
    </collision>
  </link>
  <link name="r_ankle">
    <inertial>
      <origin xyz="-0.000214 -0.018536 0.013873"/>
      <mass value="0.16710792"/>
      <inertia ixx="0.12079175" ixy="-0.00079781067" ixz="-0.00039322246" iyx="-0.00079781067" iyy="0.10885465" iyz="0.0070770117" izx="-0.00039322246" izy="0.0070770117" izz="0.041871103"/>
    </inertial>
    <visual>
      <origin rpy="0 0 0" xyz="0 0 -0.03725"/>
      <geometry>
        <box size="0.045 0.035 0.0745"/>
      </geometry>
    </visual>
    <collision>
      <origin rpy="0 0 0" xyz="0 0 -0.03725"/>
      <geometry>
        <box size="0.045 0.035 0.0745"/>
      </geometry>
    </collision>
  </link>
  <link name="r_phalange">
    <inertial>
      <origin xyz="-0.000214 -0.018536 0.013873"/>
      <mass value="0.16710792"/>
      <inertia ixx="0.12079175" ixy="-0.00079781067" ixz="-0.00039322246" iyx="-0.00079781067" iyy="0.10885465" iyz="0.0070770117" izx="-0.00039322246" izy="0.0070770117" izz="0.041871103"/>
    </inertial>
    <visual>
      <origin rpy="0 0 0" xyz="0 0 -0.03725"/>
      <geometry>
        <box size="0.02 0.02 0.0745"/>
      </geometry>
    </visual>
    <collision>
      <origin rpy="0 0 0" xyz="0 0 -0.03725"/>
      <geometry>
        <box size="0.02 0.02 0.0745"/>
      </geometry>
    </collision>
  </link>
  <joint name="r_pelvis_joint" type="revolute">
    <parent link="body"/>
    <child link="r_pelvis"/>
    <origin rpy="0 0 0" xyz="-0.0416666666667 0.05 0.0212"/>
    <axis xyz="0 0 1"/>
    <limit effort="10" lower="0" upper="0" velocity="5.6548668"/>
  </joint>
  <joint name="r_thigh_yaw_joint" type="revolute">
    <parent link="r_pelvis"/>
    <child link="r_thigh_yaw"/>
    <origin rpy="0 0 0" xyz="0 0.040875 -0.028652"/>
    <axis xyz="0 0 1"/>
    <limit effort="10" lower="0" upper="0" velocity="5.6548668"/>
  </joint>
  <joint name="r_thigh_pitch_joint" type="revolute">
    <parent link="r_thigh_yaw"/>
    <child link="r_thigh"/>
    <origin rpy="0 0 0" xyz="0 0 0"/>
    <axis xyz="0 1 0"/>
    <limit effort="10" lower="-1.308996939" upper="0.785398163397" velocity="5.6548668"/>
  </joint>
  <joint name="r_tibia_joint" type="revolute">
    <parent link="r_thigh"/>
    <child link="r_tibia"/>
    <origin rpy="0 0 0" xyz="0 0 -0.125"/>
    <axis xyz="0 1 0"/>
    <limit effort="10" lower="0.0" upper="2.61799387799" velocity="5.6548668"/>
  </joint>
  <joint name="r_ankle_joint" type="revolute">
    <parent link="r_tibia"/>
    <child link="r_ankle"/>
    <origin rpy="0 0 0" xyz="0 0 -0.13"/>
    <axis xyz="0 1 0"/>
    <limit effort="10" lower="-1.57079632679" upper="0.0" velocity="5.6548668"/>
  </joint>
  <joint name="r_phalange_joint" type="revolute">
    <parent link="r_ankle"/>
    <child link="r_phalange"/>
    <origin rpy="0 0 0" xyz="0 0 -0.0745"/>
    <axis xyz="0 1 0"/>
    <limit effort="10" lower="-0.785398163397" upper="0" velocity="5.6548668"/>
  </joint>
</robot>

