<?xml version="1.0" ?>
<!-- =================================================================================== -->
<!-- |    This document was autogenerated by xacro from body.xacro                     | -->
<!-- |    EDITING THIS FILE BY HAND IS NOT RECOMMENDED                                 | -->
<!-- =================================================================================== -->
<robot name="body" xmlns:xacro="http://www.ros.org/wiki/xacro">
  <link name="base_link"/>
  <joint name="base_link_to_body" type="fixed">
    <parent link="base_link"/>
    <child link="body"/>
  </joint>
  <link name="body">
    <inertial>
      <origin xyz="-0.003053 -0.038651 -0.019268"/>
      <mass value="0.97559947"/>
      <inertia ixx="3.1081800" ixy="-0.25460189" ixz="2.0318174" iyy="6.3787776" iyz="0.16417863" izz="5.3316425"/>
    </inertial>
    <visual>
      <!--origin xyz="-0.0235 0 -0.03525" rpy="0 0 0" /-->
      <origin rpy="0 0 0" xyz="0 0 0"/>
      <geometry>
        <box size="0.3 0.15 0.106"/>
      </geometry>
    </visual>
    <collision>
      <geometry>
        <box size="0.3 0.15 0.106"/>
      </geometry>
    </collision>
  </link>
  <!-- Arm -->
  <!--xacro:property name="body_height" value="0.106" /-->
  <!--xacro:property name="body_width" value="0.109" /-->
  <!--xacro:property name="body_large" value="0.102" /-->
  <!-- Left Arm -->
  <link name="l_pelvis">
    <inertial>
      <origin xyz="0.000000 0.000480 0.018437"/>
      <mass value="0.167"/>
      <inertia ixx="0.12259691" ixy="0.00071127469" ixz="0.00081143913" iyx="0.00071127469" iyy="0.11066637" iyz="-0.0071635476" izx="0.00081143913" izy="-0.0071635476" izz="0.041877668"/>
    </inertial>
    <visual>
      <origin rpy="0 0 0" xyz="0 0 -0.014326"/>
      <geometry>
        <box size="0.045 0.08175 0.028652"/>
      </geometry>
    </visual>
    <collision>
      <origin rpy="0 0 0" xyz="0 0 -0.014326"/>
      <geometry>
        <box size="0.045 0.08175 0.028652"/>
      </geometry>
    </collision>
  </link>
  <link name="l_thigh_yaw">
    <inertial>
      <origin xyz="0.000079 0.018242 0.013873"/>
      <mass value="0.11904336"/>
      <inertia ixx="0.097950272" ixy="0.0012119368" ixz="-0.00021223016" iyx="0.00122119368" iyy="0.032848287" iyz="-0.0019474021" izx="-0.00021223016" izy="-0.0019474021" izz="0.11493509"/>
    </inertial>
    <visual>
      <origin rpy="0 0 0" xyz="0 0 0"/>
      <geometry>
        <box size="0.001 0.001 0.001"/>
      </geometry>
    </visual>
    <collision>
      <geometry>
        <box size="0.001 0.001 0.001"/>
      </geometry>
    </collision>
  </link>
  <link name="l_thigh">
    <inertial>
      <origin xyz="-0.062965 -0.000323 0.000692"/>
      <mass value="0.11904336"/>
      <inertia ixx="0.097950272" ixy="0.0012119368" ixz="-0.00021223016" iyx="0.00122119368" iyy="0.032848287" iyz="-0.0019474021" izx="-0.00021223016" izy="-0.0019474021" izz="0.11493509"/>
    </inertial>
    <visual>
      <origin rpy="0 0 0" xyz="0 0 -0.0625"/>
      <geometry>
        <box size="0.045 0.035 0.125"/>
      </geometry>
    </visual>
    <collision>
      <origin rpy="0 0 0" xyz="0 0 -0.0625"/>
      <geometry>
        <box size="0.045 0.035 0.125"/>
      </geometry>
    </collision>
  </link>
  <link name="l_tibia">
    <inertial>
      <origin xyz="-0.053955 0.006548 -0.000592"/>
      <mass value="0.070309794"/>
      <inertia ixx="0.093369608" ixy="-0.00093567395" ixz="-0.00023992085" iyx="-0.00093567395" iyy="0.046295534" iyz="-0.012858493" izx="-0.00023992085" izy="-0.012858493" izz="0.11351516"/>
    </inertial>
    <visual>
      <origin rpy="0 0 0" xyz="0 0 -0.065"/>
      <geometry>
        <box size="0.045 0.035 0.13"/>
      </geometry>
    </visual>
    <collision>
      <origin rpy="0 0 0" xyz="0 0 -0.065"/>
      <geometry>
        <box size="0.045 0.035 0.13"/>
      </geometry>
    </collision>
  </link>
  <link name="l_ankle">
    <inertial>
      <origin xyz="-0.000214 -0.018536 0.013873"/>
      <mass value="0.16710792"/>
      <inertia ixx="0.12079175" ixy="-0.00079781067" ixz="-0.00039322246" iyx="-0.00079781067" iyy="0.10885465" iyz="0.0070770117" izx="-0.00039322246" izy="0.0070770117" izz="0.041871103"/>
    </inertial>
    <visual>
      <origin rpy="0 0 0" xyz="0 0 -0.03725"/>
      <geometry>
        <box size="0.045 0.035 0.0745"/>
      </geometry>
    </visual>
    <collision>
      <geometry>
        <box size="0.045 0.035 0.0745"/>
      </geometry>
    </collision>
  </link>
  <link name="l_phalange">
    <inertial>
      <origin xyz="-0.000214 -0.018536 0.013873"/>
      <mass value="0.16710792"/>
      <inertia ixx="0.12079175" ixy="-0.00079781067" ixz="-0.00039322246" iyx="-0.00079781067" iyy="0.10885465" iyz="0.0070770117" izx="-0.00039322246" izy="0.0070770117" izz="0.041871103"/>
    </inertial>
    <visual>
      <origin rpy="0 0 0" xyz="0 0 -0.03725"/>
      <geometry>
        <box size="0.045 0.035 0.0745"/>
      </geometry>
    </visual>
    <collision>
      <geometry>
        <box size="0.045 0.035 0.0745"/>
      </geometry>
    </collision>
  </link>
  <joint name="l_pelvis_joint" type="revolute">
    <parent link="body"/>
    <child link="l_pelvis"/>
    <origin rpy="0 0 0" xyz="0 -0.075 0"/>
    <axis xyz="0 0 1"/>
    <limit effort="10" lower="-2.6179939" upper="2.6179939" velocity="5.6548668"/>
  </joint>
  <joint name="l_thigh_yaw_joint" type="revolute">
    <parent link="l_pelvis"/>
    <child link="l_thigh_yaw"/>
    <origin rpy="0 0 0" xyz="0 -0.040875 -0.028652"/>
    <axis xyz="0 0 1"/>
    <limit effort="10" lower="-2.6179939" upper="2.6179939" velocity="5.6548668"/>
  </joint>
  <joint name="l_thigh_pitch_joint" type="revolute">
    <parent link="l_thigh_yaw"/>
    <child link="l_thigh"/>
    <origin rpy="0 0 0" xyz="0 0 0"/>
    <axis xyz="0 1 0"/>
    <limit effort="10" lower="-2.6179939" upper="2.6179939" velocity="5.6548668"/>
  </joint>
  <joint name="l_tibia_joint" type="revolute">
    <parent link="l_thigh"/>
    <child link="l_tibia"/>
    <origin rpy="0 0 0" xyz="0 0 -0.125"/>
    <axis xyz="0 1 0"/>
    <limit effort="10" lower="-2.6179939" upper="2.6179939" velocity="5.6548668"/>
  </joint>
  <joint name="l_ankle_joint" type="revolute">
    <parent link="l_tibia"/>
    <child link="l_ankle"/>
    <origin rpy="0 0 0" xyz="0 0 -0.13"/>
    <axis xyz="0 1 0"/>
    <limit effort="10" lower="-2.6179939" upper="2.6179939" velocity="5.6548668"/>
  </joint>
  <joint name="l_phalange_joint" type="revolute">
    <parent link="l_ankle"/>
    <child link="l_phalange"/>
    <origin rpy="0 0 0" xyz="0 0 -0.0745"/>
    <axis xyz="0 1 0"/>
    <limit effort="10" lower="-2.6179939" upper="2.6179939" velocity="5.6548668"/>
  </joint>
  <!-- Right Arm -->
  <link name="r_pelvis">
    <inertial>
      <origin xyz="0.000000 0.000480 0.018437"/>
      <mass value="0.167"/>
      <inertia ixx="0.12259691" ixy="0.00071127469" ixz="0.00081143913" iyx="0.00071127469" iyy="0.11066637" iyz="-0.0071635476" izx="0.00081143913" izy="-0.0071635476" izz="0.041877668"/>
    </inertial>
    <visual>
      <origin rpy="0 0 0" xyz="0 0 -0.014326"/>
      <geometry>
        <box size="0.045 0.08175 0.028652"/>
      </geometry>
    </visual>
    <collision>
      <origin rpy="0 0 0" xyz="0 0 -0.014326"/>
      <geometry>
        <box size="0.045 0.08175 0.028652"/>
      </geometry>
    </collision>
  </link>
  <link name="r_thigh_yaw">
    <inertial>
      <origin xyz="0.000079 0.018242 0.013873"/>
      <mass value="0.11904336"/>
      <inertia ixx="0.097950272" ixy="0.0012119368" ixz="-0.00021223016" iyx="0.00122119368" iyy="0.032848287" iyz="-0.0019474021" izx="-0.00021223016" izy="-0.0019474021" izz="0.11493509"/>
    </inertial>
    <visual>
      <origin rpy="0 0 0" xyz="0 0 0"/>
      <geometry>
        <box size="0.001 0.001 0.001"/>
      </geometry>
    </visual>
    <collision>
      <geometry>
        <box size="0.001 0.001 0.001"/>
      </geometry>
    </collision>
  </link>
  <link name="r_thigh">
    <inertial>
      <origin xyz="-0.062965 -0.000323 0.000692"/>
      <mass value="0.11904336"/>
      <inertia ixx="0.097950272" ixy="0.0012119368" ixz="-0.00021223016" iyx="0.00122119368" iyy="0.032848287" iyz="-0.0019474021" izx="-0.00021223016" izy="-0.0019474021" izz="0.11493509"/>
    </inertial>
    <visual>
      <origin rpy="0 0 0" xyz="0 0 -0.0625"/>
      <geometry>
        <box size="0.045 0.035 0.125"/>
      </geometry>
    </visual>
    <collision>
      <origin rpy="0 0 0" xyz="0 0 -0.0625"/>
      <geometry>
        <box size="0.045 0.035 0.125"/>
      </geometry>
    </collision>
  </link>
  <link name="r_tibia">
    <inertial>
      <origin xyz="-0.053955 0.006548 -0.000592"/>
      <mass value="0.070309794"/>
      <inertia ixx="0.093369608" ixy="-0.00093567395" ixz="-0.00023992085" iyx="-0.00093567395" iyy="0.046295534" iyz="-0.012858493" izx="-0.00023992085" izy="-0.012858493" izz="0.11351516"/>
    </inertial>
    <visual>
      <origin rpy="0 0 0" xyz="0 0 -0.065"/>
      <geometry>
        <box size="0.045 0.035 0.13"/>
      </geometry>
    </visual>
    <collision>
      <origin rpy="0 0 0" xyz="0 0 -0.065"/>
      <geometry>
        <box size="0.045 0.035 0.13"/>
      </geometry>
    </collision>
  </link>
  <link name="r_ankle">
    <inertial>
      <origin xyz="-0.000214 -0.018536 0.013873"/>
      <mass value="0.16710792"/>
      <inertia ixx="0.12079175" ixy="-0.00079781067" ixz="-0.00039322246" iyx="-0.00079781067" iyy="0.10885465" iyz="0.0070770117" izx="-0.00039322246" izy="0.0070770117" izz="0.041871103"/>
    </inertial>
    <visual>
      <origin rpy="0 0 0" xyz="0 0 -0.03725"/>
      <geometry>
        <box size="0.045 0.035 0.0745"/>
      </geometry>
    </visual>
    <collision>
      <geometry>
        <box size="0.045 0.035 0.0745"/>
      </geometry>
    </collision>
  </link>
  <link name="r_phalange">
    <inertial>
      <origin xyz="-0.000214 -0.018536 0.013873"/>
      <mass value="0.16710792"/>
      <inertia ixx="0.12079175" ixy="-0.00079781067" ixz="-0.00039322246" iyx="-0.00079781067" iyy="0.10885465" iyz="0.0070770117" izx="-0.00039322246" izy="0.0070770117" izz="0.041871103"/>
    </inertial>
    <visual>
      <origin rpy="0 0 0" xyz="0 0 -0.03725"/>
      <geometry>
        <box size="0.045 0.035 0.0745"/>
      </geometry>
    </visual>
    <collision>
      <geometry>
        <box size="0.045 0.035 0.0745"/>
      </geometry>
    </collision>
  </link>
  <joint name="r_pelvis_joint" type="revolute">
    <parent link="body"/>
    <child link="r_pelvis"/>
    <origin rpy="0 0 0" xyz="0 0.075 0"/>
    <axis xyz="0 0 1"/>
    <limit effort="10" lower="-2.6179939" upper="2.6179939" velocity="5.6548668"/>
  </joint>
  <joint name="r_thigh_yaw_joint" type="revolute">
    <parent link="r_pelvis"/>
    <child link="r_thigh_yaw"/>
    <origin rpy="0 0 0" xyz="0 0.040875 -0.028652"/>
    <axis xyz="0 0 1"/>
    <limit effort="10" lower="-2.6179939" upper="2.6179939" velocity="5.6548668"/>
  </joint>
  <joint name="r_thigh_pitch_joint" type="revolute">
    <parent link="r_thigh_yaw"/>
    <child link="r_thigh"/>
    <origin rpy="0 0 0" xyz="0 0 0"/>
    <axis xyz="0 1 0"/>
    <limit effort="10" lower="-2.6179939" upper="2.6179939" velocity="5.6548668"/>
  </joint>
  <joint name="r_tibia_joint" type="revolute">
    <parent link="r_thigh"/>
    <child link="r_tibia"/>
    <origin rpy="0 0 0" xyz="0 0 -0.125"/>
    <axis xyz="0 1 0"/>
    <limit effort="10" lower="-2.6179939" upper="2.6179939" velocity="5.6548668"/>
  </joint>
  <joint name="r_ankle_joint" type="revolute">
    <parent link="r_tibia"/>
    <child link="r_ankle"/>
    <origin rpy="0 0 0" xyz="0 0 -0.13"/>
    <axis xyz="0 1 0"/>
    <limit effort="10" lower="-2.6179939" upper="2.6179939" velocity="5.6548668"/>
  </joint>
  <joint name="r_phalange_joint" type="revolute">
    <parent link="r_ankle"/>
    <child link="r_phalange"/>
    <origin rpy="0 0 0" xyz="0 0 -0.0745"/>
    <axis xyz="0 1 0"/>
    <limit effort="10" lower="-2.6179939" upper="2.6179939" velocity="5.6548668"/>
  </joint>
</robot>

